Workbook

Sheet ok_2
A1: EMPRESS Field | B1: D2 Field | C1: D2 STAGE | D1: Formula | E1: Field
A2: Date of notification | B2: enrolledAt
A3: Organisation unit name | B3: enrollmentOrgUnitName
A4: Diagnostic Initial | B4: x0n3BxFa6SC
A5: Numero Epid | B5: a1asiVlyTbc
A6: Nom | B6: ENRjVGxVL6l
A7: Prénom | B7: sB1IHYu2xQT
A8: Date de naissance | B8: NI0QRzJvQ0k
A9: Sexe à la naissance | B9: oindugucx72
A10: Adresse du domicile | B10: Xhdn49gUd52
A11: Numéro de téléphone du cas | B11: fctSQp5nAYl
A12: Date d'apparition des symptômes | B12: DllEa3TJHNo | C12: GIb6Ge9PCc4
A13: Regional - Sensibilité à la pénicilline | B13: JrIMAA2Ubbl | C13: F9CrPrvrtb1 | D13: IF|F9CrPrvrtb1.VxdyTZMq4fz|Regional|F9CrPrvrtb1.JrIMAA2Ubbl
A14: National - Sensibilité à la pénicilline | B14: JrIMAA2Ubbl | C14: F9CrPrvrtb1 | D14: IF|F9CrPrvrtb1.VxdyTZMq4fz|National|F9CrPrvrtb1.JrIMAA2Ubbl
A15: District - Sensibilité à la pénicilline | B15: JrIMAA2Ubbl | C15: F9CrPrvrtb1 | D15: IF|F9CrPrvrtb1.VxdyTZMq4fz|District|F9CrPrvrtb1.JrIMAA2Ubbl
A16: urlFilter | D16: x0n3BxFa6SC:eq:Meningitis

Sheet Default Filters
A1: Field Name | B1: Field UID | C1: Condition
A2: Diagnostic Initial | B2: x0n3BxFa6SC | C2: eq:Meningitis

Sheet Options Mapping_2
A1: EMPRESS Field | B1: D2 Field | C1: EMPRESS Code | D1: D2 Name | E1: D2 Code | F1: D2 UID
A2: District - Sensibilité à la pénicilline | B2: JrIMAA2Ubbl | C2: =D2 -> Sensible | D2: =VLOOKUP(F2,Feuil4!A:C,3,FALSE()) -> Sensible | E2: S | F2: EVYvzEXNFUK
A3: District - Sensibilité à la pénicilline | B3: JrIMAA2Ubbl | C3: =D3 -> Résistant | D3: =VLOOKUP(F3,Feuil4!A:C,3,FALSE()) -> Résistant | E3: R | F3: u237EKffZdR
A4: District - Sensibilité à la pénicilline | B4: JrIMAA2Ubbl | C4: =D4 -> Non effectué | D4: =VLOOKUP(F4,Feuil4!A:C,3,FALSE()) -> Non effectué | E4: N | F4: Xv0Mlo3ZhTC
A5: District - Sensibilité à la pénicilline | B5: JrIMAA2Ubbl | C5: =D5 -> Intermédiaire | D5: =VLOOKUP(F5,Feuil4!A:C,3,FALSE()) -> Intermédiaire | E5: I | F5: yXpkdd4uD7W
A6: Sexe à la naissance | B6: oindugucx72 | C6: =D6 -> Masculin | D6: Masculin | E6: Male | F6: Ii4IxCLWEFn
A7: Sexe à la naissance | B7: oindugucx72 | C7: =D7 -> Féminin | D7: Féminin | E7: Female | F7: FKKrOBBFgs1
A8: Sensibilité à la pénicilline | B8: JrIMAA2Ubbl | C8: =D8 -> Non effectué | D8: =VLOOKUP(F8,Feuil4!A:C,3,FALSE()) -> Non effectué | E8: N | F8: Xv0Mlo3ZhTC

Sheet Feuil4
A1: id | B1: name | C1: displayName
A2: NBdDIRa3Rm5 | B2: 1 | C2: 1
A3: JArMXhy67fe | B3: 10A | C3: 10A
A4: xHBJ92djEAb | B4: 10F/10C/33C | C4: 10F/10C/33C
A5: WAKvomshcgJ | B5: 11A | C5: 11A
A6: G3htfTNUFbT | B6: 11A/11D | C6: 11A/11D
A7: kf4ivzbSrH9 | B7: 12A | C7: 12A
A8: fptrzTFUsJd | B8: 12F | C8: 12F
A9: kwaz8w1DGWo | B9: 12F/12A/12B/44/46 | C9: 12F/12A/12B/44/46
A10: tkKAl5t103Y | B10: 13 | C10: 13
A11: zeZTB3NQNHF | B11: 14 | C11: 14
A12: gkbcXWEuUOM | B12: 15A/15F | C12: 15A/15F
A13: kXm8ZSUdXnK | B13: 15B | C13: 15B
A14: F1eM5WiVzJi | B14: 15B/15C | C14: 15B/15C
A15: Ax1qCZf27pp | B15: 15C | C15: 15C
A16: LwHRoY86Er3 | B16: 16F | C16: 16F
A17: Fh7dnfV427M | B17: 17F | C17: 17F
A18: Yf8UHYpuhJP | B18: 18A/18B/18C/18F | C18: 18A/18B/18C/18F
A19: iZeEWefcVSi | B19: 18C | C19: 18C
A20: evF9tQ44mrX | B20: 19A | C20: 19A
A21: Sipqj23reqB | B21: 19F | C21: 19F
A22: QUOPvrMopP5 | B22: 2 | C22: 2
A23: j9bg51D2b0x | B23: 20 | C23: 20
A24: qzhSXkZwdo0 | B24: 21 | C24: 21
A25: nTb109meYkH | B25: 22F | C25: 22F
A26: wkasZX0A8wB | B26: 22F/22A | C26: 22F/22A
A27: vfEEsIFaFbY | B27: 23A | C27: 23A
A28: SmXcR3nlROf | B28: 23B | C28: 23B
A29: IgS4bOX8YwA | B29: 23F | C29: 23F
A30: C2C7kQnYQRX | B30: 24A/24B/24F | C30: 24A/24B/24F
A31: hXnMILVefGz | B31: 25F/25A/38 | C31: 25F/25A/38
A32: enu9aXVLPzJ | B32: 3 | C32: 3
A33: rvuUAhe5qiW | B33: 31 | C33: 31
A34: P6MFJpvob5I | B34: 33F | C34: 33F
A35: TqRDF4qfUau | B35: 33F/33A/37 | C35: 33F/33A/37
A36: fLdpFIZ1ZdG | B36: 34 | C36: 34
A37: i3NgGyC1mRn | B37: 35A/35C/42 | C37: 35A/35C/42
A38: gcDzU1Pxk7h | B38: 35B | C38: 35B
A39: NBtkP5CDiAg | B39: 35F/47F | C39: 35F/47F
A40: rddD6vyu7rI | B40: 38 | C40: 38
...

Sheet Feuil1
A1: D2 Field | B1: EMPRESS Field
A2: a1asiVlyTbc | B2: Numero Epid
A3: Aif45J6yuAp | B3: Date vue dans un centre santé
A4: aWLt5NgPpr1 | B4: District - Autres antibiotiques testés
A5: aWLt5NgPpr1 | B5: Regional - Autres antibiotiques testés
A6: aWLt5NgPpr1 | B6: National - Autres antibiotiques testés
A7: BEILQ6B1ilK | B7: SCB - Crises/convulsions
A8: BoIxN7Kfj07 | B8: Devenir du patient
A9: bX9jmncMHLC | B9: District - Résultat final du laboratoire
A10: bX9jmncMHLC | B10: Regional - Résultat final du laboratoire
A11: bX9jmncMHLC | B11: National - Résultat final du laboratoire
A12: CAHdBvzG00V | B12: District - Sensibilité à la ciprofloxacine
... A128: yJBRhOz5h8c | B128: Date à laquelle le cas a été notifié au district

Sheet Fields Mapping
A1: EMPRESS Field | B1: D2 Field | C1: D2 STAGE | D1: Formula | E1: Field | F1: optionSet | G1: Niveau | H1: Initial Field | I1: Field no prefix
A2: =I2 -> Date of notification | B2: enrolledAt | H2: Date of notification | I2: Date of notification
A3: =I3 -> Organisation unit name | B3: enrollmentOrgUnitName | H3: Organisation unit name | I3: Organisation unit name
A4: =I4 -> Diagnostic Initial | B4: x0n3BxFa6SC | F4: NMcuA4uVm6I | H4: Diagnostic Initial | I4: Diagnostic Initial
A5: =I5 -> Numero Epid | B5: a1asiVlyTbc | H5: Numero Epid | I5: Numero Epid
A6: =I6 -> Nom | B6: ENRjVGxVL6l | H6: Nom | I6: Nom
A7: =I7 -> Prénom | B7: sB1IHYu2xQT | H7: Prénom | I7: Prénom
A8: =I8 -> Date de naissance | B8: NI0QRzJvQ0k | H8: Date de naissance | I8: Date de naissance
A9: =I9 -> Sexe à la naissance | B9: oindugucx72 | F9: WDUwjiW2rGH | H9: Sexe à la naissance | I9: Sexe à la naissance
A10: =I10 -> Adresse du domicile | B10: Xhdn49gUd52 | H10: Adresse du domicile | I10: Adresse du domicile
A11: =I11 -> Numéro de téléphone du cas | B11: fctSQp5nAYl | H11: Numéro de téléphone du cas | I11: Numéro de téléphone du cas
A12: =I12 -> Date d'apparition des symptômes | B12: DllEa3TJHNo | C12: GIb6Ge9PCc4 | H12: SBC - Date d'apparition des symptômes | I12: Date d'apparition des symptômes
A13: =I13 -> Date vue dans un centre santé | B13: Aif45J6yuAp | C13: GIb6Ge9PCc4 | H13: SBC - Date vue dans un centre santé | I13: Date vue dans un centre santé
A14: =I14 -> Patients hospitalisés/non hospitalisés | B14: pXGhYbf5cAP | C14: GIb6Ge9PCc4 | F14: UGRaS3Y40qk | H14: SBC - Patients hospitalisés/non hospitalisés | I14: Patients hospitalisés/non hospitalisés
A15: =I15 -> Echantillon prélevé (O/N) | B15: LNRDN39NSfY | C15: GIb6Ge9PCc4 | F15: L6eMZDJkCwX | H15: SBC - Echantillon prélevé (O/N) | I15: Echantillon prélevé (O/N)
A16: =I16 -> Vaccin reçu : MenAfriVac | B16: NMLXJ99HNOw | C16: GIb6Ge9PCc4 | F16: jwAZKGa7FDo | H16: SBC - Vaccin reçu : MenAfriVac | I16: Vaccin reçu : MenAfriVac
A17: =I17 -> Date de la vaccination : MenAfriVac | B17: HhKjMQgPwuQ | C17: GIb6Ge9PCc4 | H17: SBC - Date de la vaccination : MenAfriVac | I17: Date de la vaccination : MenAfriVac
A18: =I18 -> Vaccin reçu : Vaccin méningococcique polyvalent | B18: iZvjnxwGA6Z | C18: GIb6Ge9PCc4 | F18: jwAZKGa7FDo | H18: SBC - Vaccin reçu : Vaccin méningococcique polyvalent | I18: Vaccin reçu : Vaccin méningococcique polyvalent
A19: =I19 -> Date de la vaccination : Vaccin méningococcique polyvalent | B19: uvyJmb0y5TM | C19: GIb6Ge9PCc4 | H19: SBC - Date de la vaccination : Vaccin méningococcique polyvalent | I19: Date de la vaccination : Vaccin méningococcique polyvalent
A20: =I20 -> Vaccin reçu : Hib | B20: XOcfBHNE685 | C20: GIb6Ge9PCc4 | F20: jwAZKGa7FDo | H20: SBC - Vaccin reçu : Hib | I20: Vaccin reçu : Hib
A21: =I21 -> N doses reçues : Hib | B21: poOs5h8X9CD | C21: GIb6Ge9PCc4 | H21: SBC - N doses reçues : Hib | I21: N doses reçues : Hib
A22: =I22 -> Date de la vaccination : Hib | B22: ixy37MXw6pL | C22: GIb6Ge9PCc4 | H22: SBC - Date de la vaccination : Hib | I22: Date de la vaccination : Hib
A23: =I23 -> Vaccin reçu : PCV | B23: S5h2ZUkqLD7 | C23: GIb6Ge9PCc4 | F23: jwAZKGa7FDo | H23: SBC - Vaccin reçu : PCV | I23: Vaccin reçu : PCV
A24: =I24 -> N doses reçues : PCV | B24: l7EjsU6Wu2k | C24: GIb6Ge9PCc4 | H24: SBC - N doses reçues : PCV | I24: N doses reçues : PCV
A25: =I25 -> Date de la vaccination : PCV | B25: RQyRmg1Ry0u | C25: GIb6Ge9PCc4 | H25: SBC - Date de la vaccination : PCV | I25: Date de la vaccination : PCV
A26: =I26 -> Altération de la conscience | B26: iDaqzjHTZRz | C26: GIb6Ge9PCc4 | F26: L6eMZDJkCwX | H26: SBC - Altération de la conscience | I26: Altération de la conscience
A27: =I27 -> Raideur du cou | B27: Ka2QSdJualP | C27: GIb6Ge9PCc4 | F27: L6eMZDJkCwX | H27: CBS - Raideur du cou | I27: Raideur du cou
A28: =I28 -> Fontanelle bombée | B28: XlJGFCsUzKt | C28: GIb6Ge9PCc4 | F28: L6eMZDJkCwX | H28: SBC - Fontanelle bombée | I28: Fontanelle bombée
A29: =I29 -> Fièvre | B29: S45CqdVcFXC | C29: GIb6Ge9PCc4 | F29: L6eMZDJkCwX | H29: CBS - Fièvre | I29: Fièvre
A30: =I30 -> Maux de tête | B30: wGxeDr2tfgp | C30: GIb6Ge9PCc4 | F30: L6eMZDJkCwX | H30: CBS - Maux de tête | I30: Maux de tête
A31: =I31 -> Nausées | B31: OJ0oQWQp0u6 | C31: GIb6Ge9PCc4 | F31: L6eMZDJkCwX | H31: CBS - Nausées | I31: Nausées
A32: =I32 -> Photophobie | B32: U6SJ5TnPU84 | C32: GIb6Ge9PCc4 | F32: L6eMZDJkCwX | H32: SBC - Photophobie | I32: Photophobie
A33: =I33 -> SCB - Crises/convulsions | B33: BEILQ6B1ilK | C33: GIb6Ge9PCc4 | F33: L6eMZDJkCwX | H33: SCB - Crises/convulsions | I33: SCB - Crises/convulsions
A34: =I34 -> Autres signes/symptômes, précisez | B34: heLc9SVsvjT | C34: GIb6Ge9PCc4 | H34: SBC - Autres signes/symptômes, précisez | I34: Autres signes/symptômes, précisez
A35: =I35 -> Date à laquelle le cas a été notifié au district | B35: yJBRhOz5h8c | C35: GIb6Ge9PCc4 | H35: SBC - Date à laquelle le cas a été notifié au district | I35: Date à laquelle le cas a été notifié au district
A36: =I36 -> Nom du notificateur | B36: kiCiB1aRwBe | C36: GIb6Ge9PCc4 | H36: CBS - Nom du notificateur | I36: Nom du notificateur
A37: =I37 -> Téléphone du notificateur | B37: KoYXKIRt0sH | C37: GIb6Ge9PCc4 | H37: SBC - Téléphone du notificateur | I37: Téléphone du notificateur
A38: =I38 -> Personne qui a terminé l'investigation : Nom | B38: rLl9AAjOwyf | C38: GIb6Ge9PCc4 | H38: SBC - Personne qui a terminé l'investigation : Nom | I38: Personne qui a terminé l'investigation : Nom
A39: =I39 -> Personne qui a terminé l'investigation : Contact | B39: Gun6zfKdFmp | C39: GIb6Ge9PCc4 | H39: SBC - Personne qui a terminé l'investigation : Contact | I39: Personne qui a terminé l'investigation : Contact
A40: =I40 -> ID de l'échantillon | B40: ClQKlLa5fL1 | C40: G0ePNuYPT87 | H40: CBS - ID de l'échantillon | I40: ID de l'échantillon
...

Sheet Options Mapping (2)
A1: EMPRESS Field | B1: D2 Field | C1: EMPRESS Code | D1: D2 Name | E1: D2 Code | F1: D2 UID
A2: Disease | B2: tg3fqjuPkHH | C2: Abalone Herpes | D2: Abalone Herpes | E2: ABALONE_HERPES | F2: UwAcZD55IfP
A3: Control Measure | B3: QtlBNbnLxdG | C3: Vector surveillance | D3: Vector surveillance | E3: VECTOR_SURVEILLANCE | F3: g0G6Dbsx5nB
A4: Control Measure | B4: QtlBNbnLxdG | C4: Zoning | D4: Zoning | E4: ZONING | F4: VfHVv5ZD73O

Sheet Options Mapping (3)
A1: EMPRESS Field | B1: D2 Field | C1: EMPRESS Code | D1: D2 Name | E1: D2 Code | F1: D2 UID
A2: =VLOOKUP(B2,Feuil1!A:B,2,FALSE()) -> #N/A | B2: HwSwRBG2Cpp | C2: Hi+Nm | D2: Hi+Nm | E2: Hi+Nm | F2: A2DK3hiUDxr
A3: =VLOOKUP(B3,Feuil1!A:B,2,FALSE()) -> #N/A | B3: BLiSlEmoEQH | C3: Confirmed rubella by lab | D3: Confirmed rubella by lab | E3: CR | F3: a2Yv4qpjCcA
A4: =VLOOKUP(B4,Feuil1!A:B,2,FALSE()) -> #N/A | B4: lGuhEqTT3jU | C4: Suspected septicaemia | D4: Suspected septicaemia | E4: SS | F4: a2ZW0EWI4U0
A5: =VLOOKUP(B5,Feuil1!A:B,2,FALSE()) -> #N/A | B5: zMCLYCkfLPu | C5: -20 Degrees freezer | D5: -20 Degrees freezer | E5: (-20 Degrees freezer) | F5: A3kupijmXZA
A6: =VLOOKUP(B6,Feuil1!A:B,2,FALSE()) -> #N/A | B6: ZJclgdesFio | C6: Unknown | D6: Unknown | E6: Unknown | F6: A8HHcjNFAaF
A7: =VLOOKUP(B7,Feuil1!A:B,2,FALSE()) -> #N/A | B7: omOhi3bZQac | C7: Primary | D7: Primary | E7: P | F7: aakDyGcFNwx
A8: =VLOOKUP(B8,Feuil1!A:B,2,FALSE()) -> #N/A | B8: BLiSlEmoEQH | C8: Confirmed Meningitis | D8: Confirmed Meningitis | E8: CMEN | F8: AbmVJ4IY9lv
A9: =VLOOKUP(B9,Feuil1!A:B,2,FALSE()) -> #N/A | B9: EUHTH2BvMzO | C9: Invalid | D9: Invalid | E9: Invalid | F9: abYRSAhjmqp
A10: =VLOOKUP(B10,Feuil1!A:B,2,FALSE()) -> #N/A | B10: LrneYsPjbbn | C10: PV3 NonSabin-like | D10: PV3 NonSabin-like | E10: PV3 NonSabin-like | F10: AdAUCLNoUh8
A11: =VLOOKUP(B11,Feuil1!A:B,2,FALSE()) -> #N/A | B11: sTWEbIbZUr0 | C11: cVDPV | D11: cVDPV | E11: cVDPV | F11: AdSnG8v079a
A12: =VLOOKUP(B12,Feuil1!A:B,2,FALSE()) -> #N/A | B12: KPIgrw9vFHF | C12: None | D12: None | E12: None | F12: ahwk3Ci79lN
A13: =VLOOKUP(B13,Feuil1!A:B,2,FALSE()) -> #N/A | B13: UjylMjMKDCO | C13: NPEV | D13: NPEV | E13: NPEV | F13: aI48blbEp3p
... A36: =VLOOKUP(B36,Feuil1!A:B,2,FALSE()) -> #N/A | B36: AcIsZWT4zdi | C36: Binax | D36: Binax | E36: Binax | F36: BmOUdTOPBwG
A37: =VLOOKUP(B37,Feuil1!A:B,2,FALSE()) -> District - sérotype S. pneumoniae | B37: HoNyj7eawmh | C37: 8 | D37: 8 | E37: 8 | F37: BMzihe4Rnq1
A38: =VLOOKUP(B38,Feuil1!A:B,2,FALSE()) -> #N/A | B38: AcIsZWT4zdi | C38: Biochemical identification | D38: Biochemical identification | E38: Bio | F38: bPGhgNUfrkt
A39: =VLOOKUP(B39,Feuil1!A:B,2,FALSE()) -> #N/A | B39: EUHTH2BvMzO | C39: PV1 SL | D39: PV1 SL | E39: PV1 SL | F39: BsHHLgd1MPf
A40: =VLOOKUP(B40,Feuil1!A:B,2,FALSE()) -> #N/A | B40: qh41p4G1g0G | C40: Household relative | D40: Household relative | E40: Household relative | F40: BUiMl3qNb9r
A41: =VLOOKUP(B41,Feuil1!A:B,2,FALSE()) -> #N/A | B41: pldzDqPMQsd | C41: NPENT | D41: NPENT | E41: NPENT | F41: BXhm92XlyE4
A42: =VLOOKUP(B42,Feuil1!A:B,2,FALSE()) -> District - Résultat de l'agglutination du latex | B42: IiInVS6fKH3 | C42: Not done | D42: Not done | E42: Not done | F42: BxMAmql162T
A43: =VLOOKUP(B43,Feuil1!A:B,2,FALSE()) -> District - Nom du laboratoire | B43: hN5qrbGeYnF | C43: CHR ATAKPAME | D43: CHR ATAKPAME | E43: CHR ATAKPAME | F43: bZ4GrqqrOPi
A44: =VLOOKUP(B44,Feuil1!A:B,2,FALSE()) -> #N/A | B44: EUHTH2BvMzO | C44: Not Required | D44: Not Required | E44: Not Required | F44: BzfNw6hAbsg
A45: =VLOOKUP(B45,Feuil1!A:B,2,FALSE()) -> #N/A | B45: LJfPj1oVhpe | C45: Other (specify) | D45: Other (specify) | E45: Other (specify) | F45: bznMeyWKXyQ
A46: =VLOOKUP(B46,Feuil1!A:B,2,FALSE()) -> #N/A | B46: EUHTH2BvMzO | C46: PV2 NSL | D46: PV2 NSL | E46: PV2 NSL | F46: C02DYu0V3V7
A47: =VLOOKUP(B47,Feuil1!A:B,2,FALSE()) -> District - sérotype S. pneumoniae | B47: HoNyj7eawmh | C47: 24A/24B/24F | D47: 24A/24B/24F | E47: 24A/24B/24F | F47: C2C7kQnYQRX
A48: =VLOOKUP(B48,Feuil1!A:B,2,FALSE()) -> District - Résultat final du laboratoire | B48: bX9jmncMHLC | C48: Suspect, PCR negative/inconclusive | D48: Suspect, PCR negative/inconclusive | E48: NegativePCR | F48: C7X9BEo0Gc1
A49: =VLOOKUP(B49,Feuil1!A:B,2,FALSE()) -> #N/A | B49: KPIgrw9vFHF | C49: Severe | D49: Severe | E49: Severe | F49: c96yflCNhwA
... A106: =VLOOKUP(B106,Feuil1!A:B,2,FALSE()) -> District - sérotype S. pneumoniae | B106: HoNyj7eawmh | C106: 9V | D106: 9V | E106: 9V | F106: ENcflZoXl8H
A107: =VLOOKUP(B107,Feuil1!A:B,2,FALSE()) -> District - sérotype S. pneumoniae | B107: HoNyj7eawmh | C107: 3 | D107: 3 | E107: 3 | F107: enu9aXVLPzJ
A108: =VLOOKUP(B108,Feuil1!A:B,2,FALSE()) -> #N/A | B108: nmj0fFDb8Xn | C108: Shigella - dysenteriae type1 | D108: Shigella - dysenteriae type1 | E108: Shigella - dysenteriae type1 | F108: EnwVlhcFP8D
A109: =VLOOKUP(B109,Feuil1!A:B,2,FALSE()) -> District - Résultat final du laboratoire | B109: bX9jmncMHLC | C109: Not tested | D109: Not tested | E109: NotDone | F109: eoWDNZ7Ni6D
A110: =VLOOKUP(B110,Feuil1!A:B,2,FALSE()) -> #N/A | B110: EUHTH2BvMzO | C110: PV3 SL | D110: PV3 SL | E110: PV3 SL | F110: ErcybQvi80I
A111: =VLOOKUP(B111,Feuil1!A:B,2,FALSE()) -> #N/A | B111: jI0hOmUIEmF | C111: Positive Nm A | D111: Positive Nm A | E111: Positive Nm A | F111: EspkQOlf6LW
A112: =VLOOKUP(B112,Feuil1!A:B,2,FALSE()) -> Type d'échantillon | B112: fkqcoDLvzED | C112: Isolate | D112: Isolate | E112: Isolate | F112: eSSRUiw41oM
A113: =VLOOKUP(B113,Feuil1!A:B,2,FALSE()) -> #N/A | B113: BLiSlEmoEQH | C113: Incomplete investigation | D113: Incomplete investigation | E113: Incomplete | F113: etpkV0wqbQQ
A114: =VLOOKUP(B114,Feuil1!A:B,2,FALSE()) -> District - Aspect de l'échantillon / examen macroscopique (LCR) | B114: LjgDKL4jm5K | C114: Bloody | D114: Bloody | E114: Bloody | F114: EUevWsFNccI
A115: =VLOOKUP(B115,Feuil1!A:B,2,FALSE()) -> District - sérotype S. pneumoniae | B115: HoNyj7eawmh | C115: 19A | D115: 19A | E115: 19A | F115: evF9tQ44mrX
A116: =VLOOKUP(B116,Feuil1!A:B,2,FALSE()) -> District - Sensibilité à la ceftriaxone | B116: jXANIQUFvqc | C116: Sensitive | D116: Sensitive | E116: S | F116: EVYvzEXNFUK
A117: =VLOOKUP(B117,Feuil1!A:B,2,FALSE()) -> Suivi / niveau laboratoire | B117: VxdyTZMq4fz | C117: National | D117: National | E117: National | F117: ewuzmME1qFp
A118: =VLOOKUP(B118,Feuil1!A:B,2,FALSE()) -> District - sérotype S. pneumoniae | B118: HoNyj7eawmh | C118: 9N | D118: 9N | E118: 9N | F118: eYfEd3raSPZ
...

Sheet hiddenWs
E1: Abyei | H1: Centroid Admin1 | I1: Alexandria Digital Library | L1: Active | N1: Aethina tumida is present in some bordering states of the United States. | Q1: Abalone Herpes | R1: 1 | S1: Confirmed | T1: ADT1 | U1: Captive - Amphibians | V1: Abalones | W1: Backyard/garden | AC1: No | AD1: Aesculine dihydrolase test | AF1: Afghanistan @ Central Veterinary Diagnostic and Research Laboratory (CVDRL) @ Kabul | AH1: Inconclusive | AI1: A ban has been placed on livestock and meat products entering or leaving its boundaries
E2: Afghanistan | H2: Centroid Admin2 | I2: Astodienst program | L2: CAHO | N2: Aethina tumida is present in some bordering states of the United States of America. | Q2: Acarapisosis of honey bees | R2: 10 | S2: Denied | T2: ADT2 | U2: Captive - Arthropod | V2: Accipiter gentilis | W2: Backyard/garden - Bird shop | AC2: Unknown | AD2: Agar-gel immunodiffusion (AGID) | AF2: Afghanistan @ Central diagnostic laboratory @ Kabul | AH2: Negative | AI2: All animals are aso killed to contain the outbreak
E3: Aksai Chin | H3: Centroid Admin3 | I3: CDrom WHO/UNICEF | L3: GDS | N3: After eating undercooked infected pork, blood paste | Q3: African horse sickness | R3: 11 | S3: Suspected | T3: ADT3 | U3: Captive - Birds | V3: Accipitridae (incognita) | W3: Backyard/rooftop - Household | AC3: Yes | AD3: Agar-gel precipitation (AGP) | AF3: Albania @ Veterinary Research Institute in Tirana @ Tirana | AH3: Not Testable | AI3: All the entry of border along the district have been sealed
E4: Albania | H4: Centroid Locality | I4: Collins Maps | L4: Passive | N4: After handling the carcass of a sick cow | Q4: African swine fever | R4: 12 | T4: Animal Health Inspector (AHI) | U4: Captive - Crustaceans | V4: Accipitridae (unidentified):Accipitridae (incognita)(Accipitridae) | W4: Backyard/rooftop - Village | AD4: Anatomo-pathological examination | AF4: Algeria @ Central Veterinary Laboratory, Algiers @ Algiers | AH4: Pending | AI4: Ante and post mortem inspection
E5: Algeria | H5: Exact | I5: Encyclopedia | L5: PDS | N5: Airborne spread | Q5: Akabane Disease | R5: 13 | T5: ATO | U5: Captive - Environmental sample | V5: African black Oystercatcher (Haematopus moquini) | W5: Breeding and released for hunting | AD5: Antibody detection ELISA | AF5: Algeria @ Laboratoire Vétérinaire Régional de Tlemcem @ Tlemcem | AH5: Positive | AI5: Ban all livestock products entering or exiting that farm
E6: American Samoa | H6: Unknown | I6: ESRI Web Site | L6: Routine | N6: Animal/dog bite | Q6: Algal bloom of micrcystics | R6: 14 | T6: Central TVLA (TVLA) | U6: Captive - Fish | V6: African fish eagle (Haliaeetus vocifer) | W6: Commercial | AD6: Antigen detection ELISA | AF6: Argentina @ Gerencia de Laboratorios (GELAB) @ Buenos Aires | AI6: Ban of importation of live poultry
E7: Andorra | I7: FAO field officer | L7: Sentinel | N7: Animals in an area of anthrax-infected fields | Q7: American foulbrood of honey bees | R7: 15 | T7: Central Veterinary Laboratory-Head Office (CVL) | U7: Captive - Mammal | V7: African goshawk | W7: Commercial - Bird shop | AD7: Arginine dihydrolase test | AF7: Argentina @ Instituto de Bacteriología @ Morón- Provincia de Buenos Aires | AI7: Ban of transport of eggs and poultry
E8: Angola | I8: FAO Officer | N8: Animals infected at quarantine | Q8: Amyloodinium spp infection | R8: 16 | T8: Chief Animal health Inspector (CAHI) | U8: Captive - Mollusks | V8: African Jacana | W8: Commercial - Breeding | AD8: Bacteriological examination | AF8: Argentina @ Instituto de Bacteriología, Centro de Investigaciones en Ciencias Veterinarias (CICV), @ Morón- Provincia de Buenos Aires | AI8: Ban on importing live animals and meats
E9: Anguilla | I9: GAUL 2007 | N9: Animals in transit | Q9: Anaplasma spp | R9: 17 | T9: CNASA | U9: Captive - Reptiles | V9: African masked weaver (Ploceus velatus) | W9: Commercial - Broiler | AD9: Brucellosis test | AF9: Argentina @ Institutos de Patobiología y Virología, Centro de Investigaciones en Ciencias Veterinarias y Agronómicas (CICVyA) @ Buenos Aires | AI9: Ban on transporting animals
E10: Antarctica | I10: Geonames | N10: Circulation of the virus in the Wild animal | Q10: Anthrax | R10: 18 | T10: Community Animal Health Worker (CAHW) | U10: Domestic - Amphibians | V10: African penguin (Spheniscus demersus) | W10: Commercial - Dairy | AD10: BSE Antigen Test kit | AF10: Argentina @ Laboratorio de Leptospirosis @ Buenos Aires | AI10: Breeders who have lost their pigs to the pandemic are being forced to slaughter their entire herd
E11: Antigua and Barbuda | I11: Global Gazetteer Version 2 | N11: Contact after eating infected carcasses | Q11: Arena virus | R11: 19 | T11: DAP | U11: Domestic - Arthropod | V11: African Rabbit (Oryctolagus cuniculus) | W11: Commercial - Dual purpose | AD11: Buffy coat examination | AF11: Argentina @ Malbrán Institute | AI11: Burial
E12: Argentina | I12: Google Earth | N12: Contact with affected animals | Q12: Aspergillosis | R12: 2 | T12: DD/DR | U12: Domestic - Birds | V12: African Rail | W12: Commercial - Fattening | AD12: Butter fat test | AF12: Argentina @ National Agricultural Technology Institute (INTA), Castelar @ Buenos Aires | AI12: Burning
E13: Armenia | I13: GPS | N13: Contact with animals and pigs | Q13: Atkinsiella spp | R13: 20 | T13: Director of Forestry | U13: Domestic - Crustaceans | V13: African sacred ibis (Threskiornis aethiopicus) | W13: Commercial - Free range | AD13: Calcium test in feed | AF13: Argentina @ National Institute of Human Viral Diseases "Dr. Julio I. Maistegui" @ Buenos Aires | AI13: Carry out in all markets and shops in Bishkek where meat and other livestock products are sold
E14: Aruba | I14: Map | N14: Contact with animals at market/slaughterhouses | Q14: Atresia Ani | R14: 21 | T14: Director of Livestock and Veterinary Services | U14: Domestic - Environmental sample | V14: African Yellow White-eye | W14: Commercial - Game farm | AD14: Carbohydrate fermintation test | AF14: Argentina @ Servicio national de sanidad e qualidad agroalimentaria (SENASA) | AI14: Cleaning
E15: Arunachal Pradesh | I15: maplandia.com | N15: Contact with asymptomatic animals | Q15: Atrophic Rhinitis (AR) | R15: 22 | T15: District Agriculture Officer (DAO) | U15: Domestic - Fish | V15: Allen's gallinule | W15: Commercial - Hatchery | AD15: Casein hydrolysis test | AF15: Argentina @ Zoonosis Institute "Dr Luis Pasteur", Buenos Aires @ Buenos Aires | AI15: Closure of livestock markets
E16: Ashmore and Cartier Islands | I16: National Government | N16: Contact with backyard poultry | Q16: Aujeszky's disease | R16: 23 | T16: DLO1 | U16: Domestic - Mammal | V16: Alpaca | W16: Commercial - Layer | AD16: Catalase test | AF16: Armenia @ National Laboratory of Armenia | AI16: Closure of slaughtering premises
E17: Australia | I17: NIMA | N17: Contact with chicken eggs | Q17: Avian chlamydiosis | R17: 24 | T17: DLO2 | U17: Domestic - Mollusks | V17: American badger | W17: Commercial - Live market | AD17: Centrifugation test | AF17: Armenia @ Republican Veterinary Antiepizootic and Diagnostic Center (national laboratory) - Armenia | AI17: Closure of the shop
E18: Austria | I18: OIE | N18: Contact with contaminated farming equipment, vehicles, clothing, or feed | Q18: Avian infectious bronchitis | R18: 3 | T18: DNSV | U18: Domestic - Reptiles | V18: American Crow (Corvus Brachyrhynchos) | W18: Commercial - Meat | AD18: Citrate testVoges proskaeur test | AF18: Australia @ Asia Pacific Center for Animal Health (APCAH) @ Melbourne | AI18: Confiscation
E19: Azerbaijan | I19: Other | N19: Contact with dead backyard poultry | Q19: Avian infectious laryngotracheitis | R19: 4 | T19: DPASV | U19: Wild - Amphibians | V19: American Green-winged teal | W19: Commercial - Parent stock | AD19: Coagulate test | AF19: Australia @ Australian Animal Health Laboratory (AAHL), Geelong VIC 3220, Australia | AI19: Control of arthropods
... E21: Bahamas | I21: Wikipédia | N21: Contact with humans | Q21: Avian mycoplasmosis (M. synoviae) | R21: 6 | T21: DVO1 | U21: Wild - Birds | V21: American White Pelican (Pelecanus erythrorhynchos):Pelecanidae-Phaethontiformes | W21: Commercial - Wool / Hair | AD21: Competitive ELISA (c-ELISA) | AF21: Australia @ Australian Quarantine and Inspection Service-AQIS | AI21: Control of wildlife reservoirs
E22: Bahrain | N22: Contact with infected animal at grazing/watering | Q22: Avian mycoplasmosis (M. synsheepae) | R22: 7 | T22: DVO2 | U22: Wild - Crustaceans | V22: American wigeon | W22: Hunting bird | AD22: Complement fixation test (CFT) | AF22: Australia @ Berrimah Veterinary Laboratories | AI22: Coordination with local authorities
E23: Baker Island | N23: Contact with infected animals | Q23: Avian tuberculosis | R23: 8 | T23: DVO3 | U23: Wild - Environmental sample | V23: Amur Tiger | W23: Pet | AD23: Culture for Mycoplasma | AF23: Australia @ CSIRO Animal Production @ Geelong | AI23: Culling
E24: Bangladesh | N24: Contact with infected animal (s) | Q24: Babesia spp | R24: 9 | T24: DVS | U24: Wild - Fish | V24: Anatidae (incognita) | W24: Rehabilitation center | AD24: Det Birbright | AF24: Australia @ Commonwealth Scientific and Industrial Research organisation -Australian Animal Health Laboratory @ Geelong | AI24: Culling of affected animals only
E25: Barbados | N25: Contact with infected area | Q25: Bacterial Enteric Diseases | R25: A | T25: EC | U25: Wild - Mammal | V25: Anser caerulescens: ( snow goose ) | W25: Smallholder | AD25: Direct fluorescent antibody (FAT) test | AF25: Australia @ Elizabeth Macarthur Agriculture Institute (EMAI)Virology Laboratory @ Narellan | AI25: Destruction
E26: Bassas da India | N26: Contact with live poultry in a market | Q26: Bacterial kidney disease (Renibacterium salmoninarum) | R26: APMV-I | T26: EIOS | U26: Wild - Mollusks | V26: Anserinae (unidentified):Anserinae (incognita)(Anatidae) | W26: Smallholder - Breeding | AD26: Direct immunofluorescence (DIF) | AF26: Australia @ University of Queensland @ Queensland | AI26: Destruction of carcasses
E27: Belarus | N27: Contact with poultry | Q27: Bacterial Meningitis | R27: Asia 1 | T27: Epi Unit (DVS) | U27: Wild - Reptiles | V27: Antelope | W27: Smallholder - Dairy | AD27: Direct rapid immunohistochemical test (DRIT) | AF27: Austria @ Austrian Agency for Health and Food Safety (AGES) @ Vienna | AI27: Dipping / Spraying
E28: Belgium | N28: Contact with poultry production | Q28: Bactrial necrosis/shell disease Filamentous bacterial diseases | R28: C | T28: FAO ECTAD RAF | V28: Antillean manatee (Trichecus manatus manatus) | W28: Smallholder - Dual purpose | AD28: Direct smear examination | AF28: Austria @ FAO/IAEA Central Laboratory for ELISA and Molecular Techniques in Animal Disease Diagnosis | AI28: Disinfection
E29: Belize | N29: Contact with poultry raised in the neighbourhood. | Q29: Baculovirus infection | R29: H10N3 LPAI | T29: FAO Field Officer | V29: Apis mellifera litorea | W29: Smallholder - Meat | AD29: Egg inoculaton | AF29: Azerbaijan @ National Laboratory, Bakou @ Bakou | AI29: Disinfection / Disinfestation
E30: Benin | N30: Contact with quails' eggs | Q30: Batrachochytrium dendrobatidis | R30: H10N7 LPAI | T30: FAO officer | V30: Arctic skua (or parasitic jaeger) | W30: Smallholder - Wool / Hair | AD30: Electroimmunotransfer blot assay (EITB) | AF30: Azerbaijan @ Reference Veterinary Laboratory | AI30: Education, Information and Communication
E31: Bermuda | N31: Contact with sick and dead poultry | Q31: Beetles | R31: H10N8 LPAI | T31: FAO-Report | V31: Arctic tern (Sterna paradisea) | W31: Zoo | AD31: Electron microscopy | AF31: Azerbaijan @ Republic Veterinary Laboratory | AI31: Exposure to sick and dead poultry
E32: Bhutan | N32: Contact with sick and/or dead poultry | Q32: Blackleg | R32: H1N1 | T32: Ghana Health Service | V32: Ardeidae (unspecified) | AD32: ELISA 3ABC | AF32: Azerbaijan @ State Veterinary Laboratory, Baku @ Baku | AI32: Exposure to sick and/or dead poultry
E33: Bird Island | N33: Contact with sick animals | Q33: Bluetongue | R33: H1N2 | T33: GLEWS officer | V33: Arenaria interpres | AD33: Entomological investigations | AF33: Bahrain @ National Veterinary Diagnostic Laboratory (Bahrain) | AI33: Exposure to sick or dead poultry
E34: Bolivia (Plurinational State of) | N34: Contact with sick or dead animals | Q34: Bonamia exitiosa | R34: H2N2 LPAI | T34: GPHIN | V34: Armenian gull (Larus armenicus) | AD34: Enzyme-linked immunosorbent assay (ELISA) | AF34: Bangladesh @ Bangladesh Livestock Research Institute @ Dhaka | AI34: Flooding associated with mosquito multiplication
E35: Bosnia and Herzegovina | N35: Contact with sick poultry | Q35: Bonamia ostreae | R35: H3 LPAI | T35: Health Map | V35: Asian Golden Weaver | AD35: Enzym immunoassay (EIA) membrane test | AF35: Bangladesh @ Bangladesh Livestock Research Institute, Bangladesh | AI35: General Surveillance
E36: Botswana | N36: Contact with sick or dead poultry | Q36: Botulism | R36: H3N1 | T36: International reference laboratory | V36: Asian Openbill | AD36: Floatation test | AF36: Bangladesh @ Central Disease Investigation Laboratory @ Dhaka | AI36: Implement capture of vampire bats
E37: Bouvet Island | N37: Contact with spores in the soil | Q37: Bovine anaplasmosis | R37: H3N1 LPAI | T37: LANADA | V37: Asiatic golden cat (Catopuma temminckii) | AD37: Fluorescent antibody virus | AF37: Bangladesh @ Field Disease Investigation Laboratory, Gaibandha @ Gaibandha | AI37: Imposure of a ban of consumption
E38: Brazil | N38: Contact with wild birds | Q38: Bovine babesiosis | R38: H3N2 | T38: LCV | V38: Baboon | AD38: FMDV NON- Structural Proteins | AF38: Bangladesh @ Field Disease Investigation Laboratory, Joypurhat @ Joypurhat | AI38: Isolation of the affected animal
E39: British Indian Ocean Territory | N39: Contact with wildlife | Q39: Bovine cysticercosis | R39: H3N8 | T39: Livestock Assistant | V39: Bactrian camel (Camelus bactrianus) | AD39: FMDV Structural Proteins | AF39: Bangladesh @ Institut of Epidemiology Disease Central and Research (IEDCR) | AI39: Isolation of the affected area
E40: British Virgin Islands | N40: Contact with wild species | Q40: Bovine genital campylobacteriosis | R40: H3N8 HPAI | T40: Livestock Inspector | V40: Badger | AD40: Fuorescence polarisation assay (FPA) | AF40: Belgium @ CARVA @ Liège | AI40: Maintain strict control of slaughter, sale, movement of poultry and poultry products in the communes
E41: Brunei Darussalam | N41: Contaminated animal products | Q41: Bovine spongiform encephalopathy | R41: H3N8 LPAI | T41: Livestock officer | V41: Baillon's Crake | AD41: Gelatin hydrolysis test | AF41: Belgium @ CER MARLOIE @ Namur | AI41: Modified stamping out
...
